<mujoco model="Agilex Bunker">
  <!-- Compiler options -->
  <compiler angle="radian" meshdir="assets" coordinate="local" autolimits="true"/>

  <!-- Integrator options -->
  <option timestep="0.01" cone="elliptic"/>

  <!-- Visual options -->
  <visual>
    <headlight diffuse="0.6 0.6 0.6" ambient="0.1 0.1 0.1" specular="0 0 0"/>
    <rgba haze="0.15 0.25 0.35 1"/>
    <global azimuth="120" elevation="-20"/>
  </visual>

  <!-- Configuración predeterminada -->
  <!--
  <default>
    <default class="agilex_bunker">
      <material specular="0.5" shininess="0.25"/>
	  <joint armature="0" damping="0" limited="false"/>
      <geom friction="1 0.5 0.5" rgba="0.8 0.6 0.4 1"/>
      <default class="visual">
        <geom type="mesh" group="2" contype="0" conaffinity="0"/>
      </default>
      <default class="collision">
        <geom type="mesh" group="3" mass="0" density="0"/>
      </default>
      <site size="0.001" rgba="0.5 0.5 0.5 0.3" group="4"/>
	</default>
  </default>
  -->
  <default>
    <default class="agilex_bunker">
	</default>
  </default>
	
  
  <!-- Assets and textures definitions -->
  <asset>
  
	<!-- General scene meshes and materials -->
    <texture type="skybox" builtin="gradient" rgb1="0.3 0.5 0.7" rgb2="0 0 0" width="512" height="3072"/>
    <texture type="2d" name="groundplane" builtin="checker" mark="edge" rgb1="0.2 0.3 0.4" rgb2="0.1 0.2 0.3" markrgb="0.8 0.8 0.8" width="300" height="300"/>
    <material name="groundplane" texture="groundplane" texuniform="true" texrepeat="5 5" reflectance="0.2"/>

    <!-- Bunker meshes and materials -->
    <material class="agilex_bunker" name="agilexgray" rgba="0.278 0.278 0.278 1"/>
    <material class="agilex_bunker" name="agilexblue" rgba="0.49 0.678 0.8 1"/>
	<material class="agilex_bunker" name="agilexred" rgba="0.99 0.078 0.08 1"/>
	
    <mesh file="agilex_bunker/base_Link.STL"   scale="1.5 1.5 1.5"/>
    <mesh file="agilex_bunker/base2_Link.STL"  scale="1.5 1.5 1.5"/>
    <mesh file="agilex_bunker/wheel1_Link.STL" scale="1.9 1.9 1.9"/>

  </asset>

  <!-- Worldbody and bodies definitions -->
  <worldbody>
    <light name="spotlight" mode="targetbodycom" target="mobile_base" pos="0 0 100" castshadow="false"/>
    <geom conaffinity="1" condim="3" name="floor" size="0 0 0.05" type="plane" material="groundplane"/>

    <!-- Agilex Bunker -->
    <body name="mobile_base" pos="0 0 .538" euler="0 0 0">
      <joint type="free"/> <!-- damping="150"/> -->
      <inertial mass="130.0" pos="0 0 0" diaginertia="10.443333156 10.443333156 10.72"/>
      <geom name="mobile_base_geom" type="mesh" mesh="base_Link" material="agilexgray" pos="0 0 0" size="1" />
      <geom name="mobile_base_geom_2" type="mesh" mesh="base2_Link" material="agilexblue" pos="0 0 0" size="1" />

      <!-- Right wheels -->
      <!-- Wheel Right Rear -->
	  <body name="w_rr" pos="-0.34 -0.6 -0.42" euler="1.5708 0 0">
        <joint name="w_rr_joint" pos="0 0 0" axis="0 0 -1" damping="5.1"/>
        <inertial mass="10" pos="0 0 0" diaginertia="0.443333156 0.443333156 0.72"/>
        <geom size="0.07 0.07 0.05" type="mesh" mesh="wheel1_Link" material="agilexblue" pos="0 0 0" friction="1 0.005 0.005"/><!-- condim="1" priority="1"/> -->
      </body>

      <!-- Wheel Right Center -->
      <body name="w_rc" pos="0.07 -0.6 -0.42" euler="1.5708 0 0">
        <joint name="w_rc_joint" pos="0 0 0" axis="0 0 -1" damping="5.1"/>
        <inertial mass="10" pos="0 0 0" diaginertia="0.443333156 0.443333156 0.72"/>
        <geom size="0.07 0.07 0.05" type="mesh" mesh="wheel1_Link" material="agilexblue" pos="0 0 0" friction="1 0.005 0.005"/><!-- condim="1" priority="1"/> -->
      </body>

      <!-- Wheel Right Front -->
      <body name="w_rf" pos="0.44 -0.6 -0.42" euler="1.5708 0 0">
        <joint name="w_rf_joint" pos="0 0 0" axis="0 0 -1" damping="5.1"/>
        <inertial mass="10" pos="0 0 0" diaginertia="0.443333156 0.443333156 0.72"/>
        <geom size="0.07 0.07 0.05" type="mesh" mesh="wheel1_Link" material="agilexred" pos="0 0 0" friction="1 0.005 0.005"/>
      </body>

      <!-- Left wheels -->
	  <!-- Wheel Left Rear -->
      <body name="w_lr" pos="-0.34 0.33 -0.42" euler="1.5708 0 0">
        <joint name="w_lr_joint" pos="0 0 0" axis="0 0 -1" damping="5.1"/>
        <inertial mass="10" pos="0 0 0" diaginertia="0.443333156 0.443333156 0.72"/>
        <geom size="0.07 0.07 0.05" type="mesh" mesh="wheel1_Link" material="agilexblue" pos="0 0 0" friction="1 0.005 0.005"/><!-- condim="1" priority="1"/> -->
      </body>

	  <!-- Wheel Left Center -->
      <body name="w_lc" pos="0.07 0.33 -0.42" euler="1.5708 0 0">
        <joint name="w_lc_joint" pos="0 0 0" axis="0 0 -1" damping="5.1"/>
        <inertial mass="10" pos="0 0 0" diaginertia="0.443333156 0.443333156 0.72"/>
        <geom size="0.07 0.07 0.05" type="mesh" mesh="wheel1_Link" material="agilexblue" pos="0 0 0" friction="1 0.005 0.005"/><!-- condim="1" priority="1"/> -->
      </body>

	  <!-- Wheel Left Front -->
      <body name="w_lf" pos="0.44 0.33 -0.42" euler="1.5708 0 0">
        <joint name="w_lf_joint" pos="0 0 0" axis="0 0 -1" damping="5.1"/>
        <inertial mass="10" pos="0 0 0" diaginertia="0.443333156 0.443333156 0.72"/>
        <geom size="0.07 0.07 0.05" type="mesh" mesh="wheel1_Link" material="agilexblue" pos="0 0 0" friction="1 0.005 0.005"/>
      </body>

    </body>

  </worldbody>

  <!-- Actuators -->
  
  <actuator>
	<!-- Bunker wheels -->
    <motor name="w_rr" joint="w_rr_joint" gear="1" ctrllimited="true" ctrlrange="-100 100" />
    <motor name="w_rc" joint="w_rc_joint" gear="1" ctrllimited="true" ctrlrange="-100 100" />
    <motor name="w_rf" joint="w_rf_joint" gear="1" ctrllimited="true" ctrlrange="-100 100" />
    <motor name="w_lr" joint="w_lr_joint" gear="1" ctrllimited="true" ctrlrange="-100 100" />
    <motor name="w_lc" joint="w_lc_joint" gear="1" ctrllimited="true" ctrlrange="-100 100" />
    <motor name="w_lf" joint="w_lf_joint" gear="1" ctrllimited="true" ctrlrange="-100 100" />
  </actuator>
</mujoco>
