<mujocoinclude>

    <!-- Agilex Bunker -->
      <joint type="free"/> <!-- damping="150"/> -->
      <inertial mass="130.0" pos="0 0 0" diaginertia="10.443333156 10.443333156 10.72"/>
      <geom name="mobile_base_geom" type="mesh" mesh="base_Link" material="agilexgray" pos="0 0 0" size="1" />
      <geom name="mobile_base_geom_2" type="mesh" mesh="base2_Link" material="agilexblue" pos="0 0 0" size="1" />

      <!-- Right wheels -->
      <!-- Wheel Right Rear -->
	  <body name="w_rr" pos="-0.34 -0.6 -0.42" euler="1.5708 0 0">
        <joint name="w_rr_joint" pos="0 0 0" axis="0 0 -1" damping="5.1"/>
        <inertial mass="10" pos="0 0 0" diaginertia="0.443333156 0.443333156 0.72"/>
        <geom size="0.07 0.07 0.05" type="mesh" mesh="wheel1_Link" material="agilexblue" pos="0 0 0" friction="1 0.005 0.005"/><!-- condim="1" priority="1"/> -->
      </body>

      <!-- Wheel Right Center -->
      <body name="w_rc" pos="0.07 -0.6 -0.42" euler="1.5708 0 0">
        <joint name="w_rc_joint" pos="0 0 0" axis="0 0 -1" damping="5.1"/>
        <inertial mass="10" pos="0 0 0" diaginertia="0.443333156 0.443333156 0.72"/>
        <geom size="0.07 0.07 0.05" type="mesh" mesh="wheel1_Link" material="agilexblue" pos="0 0 0" friction="1 0.005 0.005"/><!-- condim="1" priority="1"/> -->
      </body>

      <!-- Wheel Right Front -->
      <body name="w_rf" pos="0.44 -0.6 -0.42" euler="1.5708 0 0">
        <joint name="w_rf_joint" pos="0 0 0" axis="0 0 -1" damping="5.1"/>
        <inertial mass="10" pos="0 0 0" diaginertia="0.443333156 0.443333156 0.72"/>
        <geom size="0.07 0.07 0.05" type="mesh" mesh="wheel1_Link" material="agilexred" pos="0 0 0" friction="1 0.005 0.005"/>
      </body>

      <!-- Left wheels -->
	  <!-- Wheel Left Rear -->
      <body name="w_lr" pos="-0.34 0.33 -0.42" euler="1.5708 0 0">
        <joint name="w_lr_joint" pos="0 0 0" axis="0 0 -1" damping="5.1"/>
        <inertial mass="10" pos="0 0 0" diaginertia="0.443333156 0.443333156 0.72"/>
        <geom size="0.07 0.07 0.05" type="mesh" mesh="wheel1_Link" material="agilexblue" pos="0 0 0" friction="1 0.005 0.005"/><!-- condim="1" priority="1"/> -->
      </body>

	  <!-- Wheel Left Center -->
      <body name="w_lc" pos="0.07 0.33 -0.42" euler="1.5708 0 0">
        <joint name="w_lc_joint" pos="0 0 0" axis="0 0 -1" damping="5.1"/>
        <inertial mass="10" pos="0 0 0" diaginertia="0.443333156 0.443333156 0.72"/>
        <geom size="0.07 0.07 0.05" type="mesh" mesh="wheel1_Link" material="agilexblue" pos="0 0 0" friction="1 0.005 0.005"/><!-- condim="1" priority="1"/> -->
      </body>

	  <!-- Wheel Left Front -->
      <body name="w_lf" pos="0.44 0.33 -0.42" euler="1.5708 0 0">
        <joint name="w_lf_joint" pos="0 0 0" axis="0 0 -1" damping="5.1"/>
        <inertial mass="10" pos="0 0 0" diaginertia="0.443333156 0.443333156 0.72"/>
        <geom size="0.07 0.07 0.05" type="mesh" mesh="wheel1_Link" material="agilexblue" pos="0 0 0" friction="1 0.005 0.005"/>
      </body>

</mujocoinclude>
